Workbook

Sheet Inputs
A1: LCOE CALCULATOR — INPUTS
A2: Parameter | B2: Value | C2: Unit | D2: Notes
A3: A. SYSTEM CONFIGURATION
A4: System Capacity (DC STC) | B4: 1 | C4: kWp | D4: Total installed DC capacity
A5: Specific Yield | B5: 1883 | C5: kWh/kWp/yr | D5: From energy simulation (PVsyst)
A6: Annual Energy Production (E₀) | B6: =B4*B5 | C6: kWh/yr | D6: =Capacity × Specific Yield
A7: Performance Ratio (PR) | B7: 82.53 | C7: % | D7: System efficiency ratio
A8: Rated AC Power | B8: 8.754 | C8: kWac | D8: Inverter nameplate capacity
A9: DC/AC Ratio | B9: 1.14 | C9: — | D9: Inverter loading ratio
A10: Module Power | B10: 605 | C10: Wp | D10: Per-module rated power (STC)
A12: B. DEGRADATION & TEMPORAL
A13: First-Year Factor (f₁) | B13: 0.975 | C13: — | D13: Initial production factor (soiling, LID)
A14: Linear Degradation Rate (d) | B14: 0.0042 | C14: /yr | D14: Annual output decline (0.42 %/yr default)
A15: Project Lifetime (n) | B15: 25 | C15: years | D15: Bankable system design lifetime
A17: C. FINANCIAL PARAMETERS
A18: Discount Rate / WACC (r) | B18: 5 | C18: % | D18: Weighted average cost of capital
A19: O&M Cost | B19: 12 | C19: $/kWp/yr | D19: Annual operation & maintenance
A20: Tariff / PPA Rate | B20: 0.09 | C20: $/kWh | D20: Energy sale price (constant)
A22: D. LCOE RATING THRESHOLDS
A23: Excellent — max LCOE | B23: 0.034 | C23: $/kWh | D23: LCOE below this threshold = Excellent
A24: Low — min LCOE | B24: 0.045 | C24: $/kWh | D24: LCOE above this threshold = Low (Acceptable in between)
A26: Colour legend: Blue = hardcoded input (change freely) | Black = formula (do not edit) | Green = cross-sheet link

Sheet CAPEX
A1: CAPITAL EXPENDITURE (CAPEX) BREAKDOWN
A2: Item | B2: Notes | C2: $/kWp | D2: Total ($) | E2: % of Total
A3: Module & Inverter Hardware
A4: Modules | C4: 200 | D4: =C4*Inputs!B4 | E4: =IF(C31=0,0,C4/C31)
A5: Inverters | C5: 80 | D5: =C5*Inputs!B4 | E5: =IF(C31=0,0,C5/C31)
A6: Module & Inverter Hardware — Subtotal | C6: =SUM(C4:C5) | D6: =SUM(D4:D5)
A8: Balance of System (BOS)
A9: Racking & Mounting | C9: 100 | D9: =C9*Inputs!B4 | E9: =IF(C31=0,0,C9/C31)
A10: Grid Connection | C10: 40 | D10: =C10*Inputs!B4 | E10: =IF(C31=0,0,C10/C31)
A11: Cabling / Wiring | C11: 40 | D11: =C11*Inputs!B4 | E11: =IF(C31=0,0,C11/C31)
A12: Safety & Security | C12: 7.6 | D12: =C12*Inputs!B4 | E12: =IF(C31=0,0,C12/C31)
A13: Monitoring & Control | C13: 3.2 | D13: =C13*Inputs!B4 | E13: =IF(C31=0,0,C13/C31)
A14: Balance of System (BOS) — Subtotal | C14: =SUM(C9:C13) | D14: =SUM(D9:D13)
A16: Installation
A17: Mechanical Installation | C17: 60 | D17: =C17*Inputs!B4 | E17: =IF(C31=0,0,C17/C31)
A18: Electrical Installation | C18: 56.9 | D18: =C18*Inputs!B4 | E18: =IF(C31=0,0,C18/C31)
A19: Inspection | C19: 8.2 | D19: =C19*Inputs!B4 | E19: =IF(C31=0,0,C19/C31)
A20: Installation — Subtotal | C20: =SUM(C17:C19) | D20: =SUM(D17:D19)
A22: Soft Costs
A23: Margin | C23: 47 | D23: =C23*Inputs!B4 | E23: =IF(C31=0,0,C23/C31)
A24: Financing Costs | C24: 3.4 | D24: =C24*Inputs!B4 | E24: =IF(C31=0,0,C24/C31)
A25: System Design | C25: 8.7 | D25: =C25*Inputs!B4 | E25: =IF(C31=0,0,C25/C31)
A26: Permitting | C26: 12.9 | D26: =C26*Inputs!B4 | E26: =IF(C31=0,0,C26/C31)
A27: Incentive Application | C27: 10.9 | D27: =C27*Inputs!B4 | E27: =IF(C31=0,0,C27/C31)
A28: Customer Acquisition | C28: 3.5 | D28: =C28*Inputs!B4 | E28: =IF(C31=0,0,C28/C31)
A29: Soft Costs — Subtotal | C29: =SUM(C23:C28) | D29: =SUM(D23:D28)
A31: GRAND TOTAL — $/kWp | C31: =C6+C14+C20+C29 | D31: =C31*Inputs!B4 | E31: 100%
A33: Note: Blue cells ($/kWp) are editable. Total ($) = $/kWp × System Capacity (Inputs!B4). Default total = 682.3 $/kWp.

Sheet Schedule
A1: ANNUAL ENERGY PRODUCTION & CASH FLOW SCHEDULE
A2: Year | B2: Deg. Factor (%) | C2: Energy (MWh) | D2: [LCOE] Disc. Energy (kWh) | E2: [LCOE] Disc. O&M ($) | F2: Revenue (undiscounted $) | G2: [CF] Disc. Revenue ($) | H2: [CF] Disc. CAPEX ($) | I2: [CF] Disc. O&M ($) | J2: [CF] Disc. Net CF ($) | K2: [CF] Cumulative Disc. CF ($) | L2: Active (≤ Lifetime)
A3: 1 | B3: =IF(1<=Inputs!B15,1,0)*MAX(0,Inputs!B13-Inputs!B14*1) | C3: =IF(1<=Inputs!B15,1,0)*Inputs!B6*MAX(0,Inputs!B13-Inputs!B14*1)/1000 | D3: =IF(1<=Inputs!B15,1,0)*Inputs!B6*MAX(0,Inputs!B13-Inputs!B14*1)/((1+Inputs!B18/100)^1) | E3: =IF(1<=Inputs!B15,1,0)*Inputs!B19*Inputs!B4/((1+Inputs!B18/100)^1) | F3: =IF(1<=Inputs!B15,1,0)*Inputs!B6*MAX(0,Inputs!B13-Inputs!B14*1)*Inputs!B20 | G3: =IF(1<=Inputs!B15,1,0)*Inputs!B6*MAX(0,Inputs!B13-Inputs!B14*1)*Inputs!B20/((1+Inputs!B18/100)^(1-1)) | H3: =CAPEX!D31 | I3: =IF(1<=Inputs!B15,1,0)*Inputs!B19*Inputs!B4/((1+Inputs!B18/100)^(1-1)) | J3: =G3-I3-H3 | K3: =J3 | L3: =IF(1<=Inputs!B15,"Yes","")
A4: 2 | B4: =IF(2<=Inputs!B15,1,0)*MAX(0,Inputs!B13-Inputs!B14*2) | C4: =IF(2<=Inputs!B15,1,0)*Inputs!B6*MAX(0,Inputs!B13-Inputs!B14*2)/1000 | D4: =IF(2<=Inputs!B15,1,0)*Inputs!B6*MAX(0,Inputs!B13-Inputs!B14*2)/((1+Inputs!B18/100)^2) | E4: =IF(2<=Inputs!B15,1,0)*Inputs!B19*Inputs!B4/((1+Inputs!B18/100)^2) | F4: =IF(2<=Inputs!B15,1,0)*Inputs!B6*MAX(0,Inputs!B13-Inputs!B14*2)*Inputs!B20 | G4: =IF(2<=Inputs!B15,1,0)*Inputs!B6*MAX(0,Inputs!B13-Inputs!B14*2)*Inputs!B20/((1+Inputs!B18/100)^(2-1)) | H4: 0 | I4: =IF(2<=Inputs!B15,1,0)*Inputs!B19*Inputs!B4/((1+Inputs!B18/100)^(2-1)) | J4: =G4-I4-H4 | K4: =K3+J4 | L4: =IF(2<=Inputs!B15,"Yes","")
A5: 3 | B5: =IF(3<=Inputs!B15,1,0)*MAX(0,Inputs!B13-Inputs!B14*3) | C5: =IF(3<=Inputs!B15,1,0)*Inputs!B6*MAX(0,Inputs!B13-Inputs!B14*3)/1000 | D5: =IF(3<=Inputs!B15,1,0)*Inputs!B6*MAX(0,Inputs!B13-Inputs!B14*3)/((1+Inputs!B18/100)^3) | E5: =IF(3<=Inputs!B15,1,0)*Inputs!B19*Inputs!B4/((1+Inputs!B18/100)^3) | F5: =IF(3<=Inputs!B15,1,0)*Inputs!B6*MAX(0,Inputs!B13-Inputs!B14*3)*Inputs!B20 | G5: =IF(3<=Inputs!B15,1,0)*Inputs!B6*MAX(0,Inputs!B13-Inputs!B14*3)*Inputs!B20/((1+Inputs!B18/100)^(3-1)) | H5: 0 | I5: =IF(3<=Inputs!B15,1,0)*Inputs!B19*Inputs!B4/((1+Inputs!B18/100)^(3-1)) | J5: =G5-I5-H5 | K5: =K4+J5 | L5: =IF(3<=Inputs!B15,"Yes","")
A6: 4 | B6: =IF(4<=Inputs!B15,1,0)*MAX(0,Inputs!B13-Inputs!B14*4) | C6: =IF(4<=Inputs!B15,1,0)*Inputs!B6*MAX(0,Inputs!B13-Inputs!B14*4)/1000 | D6: =IF(4<=Inputs!B15,1,0)*Inputs!B6*MAX(0,Inputs!B13-Inputs!B14*4)/((1+Inputs!B18/100)^4) | E6: =IF(4<=Inputs!B15,1,0)*Inputs!B19*Inputs!B4/((1+Inputs!B18/100)^4) | F6: =IF(4<=Inputs!B15,1,0)*Inputs!B6*MAX(0,Inputs!B13-Inputs!B14*4)*Inputs!B20 | G6: =IF(4<=Inputs!B15,1,0)*Inputs!B6*MAX(0,Inputs!B13-Inputs!B14*4)*Inputs!B20/((1+Inputs!B18/100)^(4-1)) | H6: 0 | I6: =IF(4<=Inputs!B15,1,0)*Inputs!B19*Inputs!B4/((1+Inputs!B18/100)^(4-1)) | J6: =G6-I6-H6 | K6: =K5+J6 | L6: =IF(4<=Inputs!B15,"Yes","")
A7: 5 | B7: =IF(5<=Inputs!B15,1,0)*MAX(0,Inputs!B13-Inputs!B14*5) | C7: =IF(5<=Inputs!B15,1,0)*Inputs!B6*MAX(0,Inputs!B13-Inputs!B14*5)/1000 | D7: =IF(5<=Inputs!B15,1,0)*Inputs!B6*MAX(0,Inputs!B13-Inputs!B14*5)/((1+Inputs!B18/100)^5) | E7: =IF(5<=Inputs!B15,1,0)*Inputs!B19*Inputs!B4/((1+Inputs!B18/100)^5) | F7: =IF(5<=Inputs!B15,1,0)*Inputs!B6*MAX(0,Inputs!B13-Inputs!B14*5)*Inputs!B20 | G7: =IF(5<=Inputs!B15,1,0)*Inputs!B6*MAX(0,Inputs!B13-Inputs!B14*5)*Inputs!B20/((1+Inputs!B18/100)^(5-1)) | H7: 0 | I7: =IF(5<=Inputs!B15,1,0)*Inputs!B19*Inputs!B4/((1+Inputs!B18/100)^(5-1)) | J7: =G7-I7-H7 | K7: =K6+J7 | L7: =IF(5<=Inputs!B15,"Yes","")
A8: 6 | B8: =IF(6<=Inputs!B15,1,0)*MAX(0,Inputs!B13-Inputs!B14*6) | C8: =IF(6<=Inputs!B15,1,0)*Inputs!B6*MAX(0,Inputs!B13-Inputs!B14*6)/1000 | D8: =IF(6<=Inputs!B15,1,0)*Inputs!B6*MAX(0,Inputs!B13-Inputs!B14*6)/((1+Inputs!B18/100)^6) | E8: =IF(6<=Inputs!B15,1,0)*Inputs!B19*Inputs!B4/((1+Inputs!B18/100)^6) | F8: =IF(6<=Inputs!B15,1,0)*Inputs!B6*MAX(0,Inputs!B13-Inputs!B14*6)*Inputs!B20 | G8: =IF(6<=Inputs!B15,1,0)*Inputs!B6*MAX(0,Inputs!B13-Inputs!B14*6)*Inputs!B20/((1+Inputs!B18/100)^(6-1)) | H8: 0 | I8: =IF(6<=Inputs!B15,1,0)*Inputs!B19*Inputs!B4/((1+Inputs!B18/100)^(6-1)) | J8: =G8-I8-H8 | K8: =K7+J8 | L8: =IF(6<=Inputs!B15,"Yes","")
A9: 7 | B9: =IF(7<=Inputs!B15,1,0)*MAX(0,Inputs!B13-Inputs!B14*7) | C9: =IF(7<=Inputs!B15,1,0)*Inputs!B6*MAX(0,Inputs!B13-Inputs!B14*7)/1000 | D9: =IF(7<=Inputs!B15,1,0)*Inputs!B6*MAX(0,Inputs!B13-Inputs!B14*7)/((1+Inputs!B18/100)^7) | E9: =IF(7<=Inputs!B15,1,0)*Inputs!B19*Inputs!B4/((1+Inputs!B18/100)^7) | F9: =IF(7<=Inputs!B15,1,0)*Inputs!B6*MAX(0,Inputs!B13-Inputs!B14*7)*Inputs!B20 | G9: =IF(7<=Inputs!B15,1,0)*Inputs!B6*MAX(0,Inputs!B13-Inputs!B14*7)*Inputs!B20/((1+Inputs!B18/100)^(7-1)) | H9: 0 | I9: =IF(7<=Inputs!B15,1,0)*Inputs!B19*Inputs!B4/((1+Inputs!B18/100)^(7-1)) | J9: =G9-I9-H9 | K9: =K8+J9 | L9: =IF(7<=Inputs!B15,"Yes","")
A10: 8 | B10: =IF(8<=Inputs!B15,1,0)*MAX(0,Inputs!B13-Inputs!B14*8) | C10: =IF(8<=Inputs!B15,1,0)*Inputs!B6*MAX(0,Inputs!B13-Inputs!B14*8)/1000 | D10: =IF(8<=Inputs!B15,1,0)*Inputs!B6*MAX(0,Inputs!B13-Inputs!B14*8)/((1+Inputs!B18/100)^8) | E10: =IF(8<=Inputs!B15,1,0)*Inputs!B19*Inputs!B4/((1+Inputs!B18/100)^8) | F10: =IF(8<=Inputs!B15,1,0)*Inputs!B6*MAX(0,Inputs!B13-Inputs!B14*8)*Inputs!B20 | G10: =IF(8<=Inputs!B15,1,0)*Inputs!B6*MAX(0,Inputs!B13-Inputs!B14*8)*Inputs!B20/((1+Inputs!B18/100)^(8-1)) | H10: 0 | I10: =IF(8<=Inputs!B15,1,0)*Inputs!B19*Inputs!B4/((1+Inputs!B18/100)^(8-1)) | J10: =G10-I10-H10 | K10: =K9+J10 | L10: =IF(8<=Inputs!B15,"Yes","")
A11: 9 | B11: =IF(9<=Inputs!B15,1,0)*MAX(0,Inputs!B13-Inputs!B14*9) | C11: =IF(9<=Inputs!B15,1,0)*Inputs!B6*MAX(0,Inputs!B13-Inputs!B14*9)/1000 | D11: =IF(9<=Inputs!B15,1,0)*Inputs!B6*MAX(0,Inputs!B13-Inputs!B14*9)/((1+Inputs!B18/100)^9) | E11: =IF(9<=Inputs!B15,1,0)*Inputs!B19*Inputs!B4/((1+Inputs!B18/100)^9) | F11: =IF(9<=Inputs!B15,1,0)*Inputs!B6*MAX(0,Inputs!B13-Inputs!B14*9)*Inputs!B20 | G11: =IF(9<=Inputs!B15,1,0)*Inputs!B6*MAX(0,Inputs!B13-Inputs!B14*9)*Inputs!B20/((1+Inputs!B18/100)^(9-1)) | H11: 0 | I11: =IF(9<=Inputs!B15,1,0)*Inputs!B19*Inputs!B4/((1+Inputs!B18/100)^(9-1)) | J11: =G11-I11-H11 | K11: =K10+J11 | L11: =IF(9<=Inputs!B15,"Yes","")
A12: 10 | B12: =IF(10<=Inputs!B15,1,0)*MAX(0,Inputs!B13-Inputs!B14*10) | C12: =IF(10<=Inputs!B15,1,0)*Inputs!B6*MAX(0,Inputs!B13-Inputs!B14*10)/1000 | D12: =IF(10<=Inputs!B15,1,0)*Inputs!B6*MAX(0,Inputs!B13-Inputs!B14*10)/((1+Inputs!B18/100)^10) | E12: =IF(10<=Inputs!B15,1,0)*Inputs!B19*Inputs!B4/((1+Inputs!B18/100)^10) | F12: =IF(10<=Inputs!B15,1,0)*Inputs!B6*MAX(0,Inputs!B13-Inputs!B14*10)*Inputs!B20 | G12: =IF(10<=Inputs!B15,1,0)*Inputs!B6*MAX(0,Inputs!B13-Inputs!B14*10)*Inputs!B20/((1+Inputs!B18/100)^(10-1)) | H12: 0 | I12: =IF(10<=Inputs!B15,1,0)*Inputs!B19*Inputs!B4/((1+Inputs!B18/100)^(10-1)) | J12: =G12-I12-H12 | K12: =K11+J12 | L12: =IF(10<=Inputs!B15,"Yes","")
A13: 11 | B13: =IF(11<=Inputs!B15,1,0)*MAX(0,Inputs!B13-Inputs!B14*11) | C13: =IF(11<=Inputs!B15,1,0)*Inputs!B6*MAX(0,Inputs!B13-Inputs!B14*11)/1000 | D13: =IF(11<=Inputs!B15,1,0)*Inputs!B6*MAX(0,Inputs!B13-Inputs!B14*11)/((1+Inputs!B18/100)^11) | E13: =IF(11<=Inputs!B15,1,0)*Inputs!B19*Inputs!B4/((1+Inputs!B18/100)^11) | F13: =IF(11<=Inputs!B15,1,0)*Inputs!B6*MAX(0,Inputs!B13-Inputs!B14*11)*Inputs!B20 | G13: =IF(11<=Inputs!B15,1,0)*Inputs!B6*MAX(0,Inputs!B13-Inputs!B14*11)*Inputs!B20/((1+Inputs!B18/100)^(11-1)) | H13: 0 | I13: =IF(11<=Inputs!B15,1,0)*Inputs!B19*Inputs!B4/((1+Inputs!B18/100)^(11-1)) | J13: =G13-I13-H13 | K13: =K12+J13 | L13: =IF(11<=Inputs!B15,"Yes","")
A14: 12 | B14: =IF(12<=Inputs!B15,1,0)*MAX(0,Inputs!B13-Inputs!B14*12) | C14: =IF(12<=Inputs!B15,1,0)*Inputs!B6*MAX(0,Inputs!B13-Inputs!B14*12)/1000 | D14: =IF(12<=Inputs!B15,1,0)*Inputs!B6*MAX(0,Inputs!B13-Inputs!B14*12)/((1+Inputs!B18/100)^12) | E14: =IF(12<=Inputs!B15,1,0)*Inputs!B19*Inputs!B4/((1+Inputs!B18/100)^12) | F14: =IF(12<=Inputs!B15,1,0)*Inputs!B6*MAX(0,Inputs!B13-Inputs!B14*12)*Inputs!B20 | G14: =IF(12<=Inputs!B15,1,0)*Inputs!B6*MAX(0,Inputs!B13-Inputs!B14*12)*Inputs!B20/((1+Inputs!B18/100)^(12-1)) | H14: 0 | I14: =IF(12<=Inputs!B15,1,0)*Inputs!B19*Inputs!B4/((1+Inputs!B18/100)^(12-1)) | J14: =G14-I14-H14 | K14: =K13+J14 | L14: =IF(12<=Inputs!B15,"Yes","")
A15: 13 | B15: =IF(13<=Inputs!B15,1,0)*MAX(0,Inputs!B13-Inputs!B14*13) | C15: =IF(13<=Inputs!B15,1,0)*Inputs!B6*MAX(0,Inputs!B13-Inputs!B14*13)/1000 | D15: =IF(13<=Inputs!B15,1,0)*Inputs!B6*MAX(0,Inputs!B13-Inputs!B14*13)/((1+Inputs!B18/100)^13) | E15: =IF(13<=Inputs!B15,1,0)*Inputs!B19*Inputs!B4/((1+Inputs!B18/100)^13) | F15: =IF(13<=Inputs!B15,1,0)*Inputs!B6*MAX(0,Inputs!B13-Inputs!B14*13)*Inputs!B20 | G15: =IF(13<=Inputs!B15,1,0)*Inputs!B6*MAX(0,Inputs!B13-Inputs!B14*13)*Inputs!B20/((1+Inputs!B18/100)^(13-1)) | H15: 0 | I15: =IF(13<=Inputs!B15,1,0)*Inputs!B19*Inputs!B4/((1+Inputs!B18/100)^(13-1)) | J15: =G15-I15-H15 | K15: =K14+J15 | L15: =IF(13<=Inputs!B15,"Yes","")
A16: 14 | B16: =IF(14<=Inputs!B15,1,0)*MAX(0,Inputs!B13-Inputs!B14*14) | C16: =IF(14<=Inputs!B15,1,0)*Inputs!B6*MAX(0,Inputs!B13-Inputs!B14*14)/1000 | D16: =IF(14<=Inputs!B15,1,0)*Inputs!B6*MAX(0,Inputs!B13-Inputs!B14*14)/((1+Inputs!B18/100)^14) | E16: =IF(14<=Inputs!B15,1,0)*Inputs!B19*Inputs!B4/((1+Inputs!B18/100)^14) | F16: =IF(14<=Inputs!B15,1,0)*Inputs!B6*MAX(0,Inputs!B13-Inputs!B14*14)*Inputs!B20 | G16: =IF(14<=Inputs!B15,1,0)*Inputs!B6*MAX(0,Inputs!B13-Inputs!B14*14)*Inputs!B20/((1+Inputs!B18/100)^(14-1)) | H16: 0 | I16: =IF(14<=Inputs!B15,1,0)*Inputs!B19*Inputs!B4/((1+Inputs!B18/100)^(14-1)) | J16: =G16-I16-H16 | K16: =K15+J16 | L16: =IF(14<=Inputs!B15,"Yes","")
A17: 15 | B17: =IF(15<=Inputs!B15,1,0)*MAX(0,Inputs!B13-Inputs!B14*15) | C17: =IF(15<=Inputs!B15,1,0)*Inputs!B6*MAX(0,Inputs!B13-Inputs!B14*15)/1000 | D17: =IF(15<=Inputs!B15,1,0)*Inputs!B6*MAX(0,Inputs!B13-Inputs!B14*15)/((1+Inputs!B18/100)^15) | E17: =IF(15<=Inputs!B15,1,0)*Inputs!B19*Inputs!B4/((1+Inputs!B18/100)^15) | F17: =IF(15<=Inputs!B15,1,0)*Inputs!B6*MAX(0,Inputs!B13-Inputs!B14*15)*Inputs!B20 | G17: =IF(15<=Inputs!B15,1,0)*Inputs!B6*MAX(0,Inputs!B13-Inputs!B14*15)*Inputs!B20/((1+Inputs!B18/100)^(15-1)) | H17: 0 | I17: =IF(15<=Inputs!B15,1,0)*Inputs!B19*Inputs!B4/((1+Inputs!B18/100)^(15-1)) | J17: =G17-I17-H17 | K17: =K16+J17 | L17: =IF(15<=Inputs!B15,"Yes","")
A18: 16 | B18: =IF(16<=Inputs!B15,1,0)*MAX(0,Inputs!B13-Inputs!B14*16) | C18: =IF(16<=Inputs!B15,1,0)*Inputs!B6*MAX(0,Inputs!B13-Inputs!B14*16)/1000 | D18: =IF(16<=Inputs!B15,1,0)*Inputs!B6*MAX(0,Inputs!B13-Inputs!B14*16)/((1+Inputs!B18/100)^16) | E18: =IF(16<=Inputs!B15,1,0)*Inputs!B19*Inputs!B4/((1+Inputs!B18/100)^16) | F18: =IF(16<=Inputs!B15,1,0)*Inputs!B6*MAX(0,Inputs!B13-Inputs!B14*16)*Inputs!B20 | G18: =IF(16<=Inputs!B15,1,0)*Inputs!B6*MAX(0,Inputs!B13-Inputs!B14*16)*Inputs!B20/((1+Inputs!B18/100)^(16-1)) | H18: 0 | I18: =IF(16<=Inputs!B15,1,0)*Inputs!B19*Inputs!B4/((1+Inputs!B18/100)^(16-1)) | J18: =G18-I18-H18 | K18: =K17+J18 | L18: =IF(16<=Inputs!B15,"Yes","")
A19: 17 | B19: =IF(17<=Inputs!B15,1,0)*MAX(0,Inputs!B13-Inputs!B14*17) | C19: =IF(17<=Inputs!B15,1,0)*Inputs!B6*MAX(0,Inputs!B13-Inputs!B14*17)/1000 | D19: =IF(17<=Inputs!B15,1,0)*Inputs!B6*MAX(0,Inputs!B13-Inputs!B14*17)/((1+Inputs!B18/100)^17) | E19: =IF(17<=Inputs!B15,1,0)*Inputs!B19*Inputs!B4/((1+Inputs!B18/100)^17) | F19: =IF(17<=Inputs!B15,1,0)*Inputs!B6*MAX(0,Inputs!B13-Inputs!B14*17)*Inputs!B20 | G19: =IF(17<=Inputs!B15,1,0)*Inputs!B6*MAX(0,Inputs!B13-Inputs!B14*17)*Inputs!B20/((1+Inputs!B18/100)^(17-1)) | H19: 0 | I19: =IF(17<=Inputs!B15,1,0)*Inputs!B19*Inputs!B4/((1+Inputs!B18/100)^(17-1)) | J19: =G19-I19-H19 | K19: =K18+J19 | L19: =IF(17<=Inputs!B15,"Yes","")
A20: 18 | B20: =IF(18<=Inputs!B15,1,0)*MAX(0,Inputs!B13-Inputs!B14*18) | C20: =IF(18<=Inputs!B15,1,0)*Inputs!B6*MAX(0,Inputs!B13-Inputs!B14*18)/1000 | D20: =IF(18<=Inputs!B15,1,0)*Inputs!B6*MAX(0,Inputs!B13-Inputs!B14*18)/((1+Inputs!B18/100)^18) | E20: =IF(18<=Inputs!B15,1,0)*Inputs!B19*Inputs!B4/((1+Inputs!B18/100)^18) | F20: =IF(18<=Inputs!B15,1,0)*Inputs!B6*MAX(0,Inputs!B13-Inputs!B14*18)*Inputs!B20 | G20: =IF(18<=Inputs!B15,1,0)*Inputs!B6*MAX(0,Inputs!B13-Inputs!B14*18)*Inputs!B20/((1+Inputs!B18/100)^(18-1)) | H20: 0 | I20: =IF(18<=Inputs!B15,1,0)*Inputs!B19*Inputs!B4/((1+Inputs!B18/100)^(18-1)) | J20: =G20-I20-H20 | K20: =K19+J20 | L20: =IF(18<=Inputs!B15,"Yes","")
A21: 19 | B21: =IF(19<=Inputs!B15,1,0)*MAX(0,Inputs!B13-Inputs!B14*19) | C21: =IF(19<=Inputs!B15,1,0)*Inputs!B6*MAX(0,Inputs!B13-Inputs!B14*19)/1000 | D21: =IF(19<=Inputs!B15,1,0)*Inputs!B6*MAX(0,Inputs!B13-Inputs!B14*19)/((1+Inputs!B18/100)^19) | E21: =IF(19<=Inputs!B15,1,0)*Inputs!B19*Inputs!B4/((1+Inputs!B18/100)^19) | F21: =IF(19<=Inputs!B15,1,0)*Inputs!B6*MAX(0,Inputs!B13-Inputs!B14*19)*Inputs!B20 | G21: =IF(19<=Inputs!B15,1,0)*Inputs!B6*MAX(0,Inputs!B13-Inputs!B14*19)*Inputs!B20/((1+Inputs!B18/100)^(19-1)) | H21: 0 | I21: =IF(19<=Inputs!B15,1,0)*Inputs!B19*Inputs!B4/((1+Inputs!B18/100)^(19-1)) | J21: =G21-I21-H21 | K21: =K20+J21 | L21: =IF(19<=Inputs!B15,"Yes","")
A22: 20 | B22: =IF(20<=Inputs!B15,1,0)*MAX(0,Inputs!B13-Inputs!B14*20) | C22: =IF(20<=Inputs!B15,1,0)*Inputs!B6*MAX(0,Inputs!B13-Inputs!B14*20)/1000 | D22: =IF(20<=Inputs!B15,1,0)*Inputs!B6*MAX(0,Inputs!B13-Inputs!B14*20)/((1+Inputs!B18/100)^20) | E22: =IF(20<=Inputs!B15,1,0)*Inputs!B19*Inputs!B4/((1+Inputs!B18/100)^20) | F22: =IF(20<=Inputs!B15,1,0)*Inputs!B6*MAX(0,Inputs!B13-Inputs!B14*20)*Inputs!B20 | G22: =IF(20<=Inputs!B15,1,0)*Inputs!B6*MAX(0,Inputs!B13-Inputs!B14*20)*Inputs!B20/((1+Inputs!B18/100)^(20-1)) | H22: 0 | I22: =IF(20<=Inputs!B15,1,0)*Inputs!B19*Inputs!B4/((1+Inputs!B18/100)^(20-1)) | J22: =G22-I22-H22 | K22: =K21+J22 | L22: =IF(20<=Inputs!B15,"Yes","")
A23: 21 | B23: =IF(21<=Inputs!B15,1,0)*MAX(0,Inputs!B13-Inputs!B14*21) | C23: =IF(21<=Inputs!B15,1,0)*Inputs!B6*MAX(0,Inputs!B13-Inputs!B14*21)/1000 | D23: =IF(21<=Inputs!B15,1,0)*Inputs!B6*MAX(0,Inputs!B13-Inputs!B14*21)/((1+Inputs!B18/100)^21) | E23: =IF(21<=Inputs!B15,1,0)*Inputs!B19*Inputs!B4/((1+Inputs!B18/100)^21) | F23: =IF(21<=Inputs!B15,1,0)*Inputs!B6*MAX(0,Inputs!B13-Inputs!B14*21)*Inputs!B20 | G23: =IF(21<=Inputs!B15,1,0)*Inputs!B6*MAX(0,Inputs!B13-Inputs!B14*21)*Inputs!B20/((1+Inputs!B18/100)^(21-1)) | H23: 0 | I23: =IF(21<=Inputs!B15,1,0)*Inputs!B19*Inputs!B4/((1+Inputs!B18/100)^(21-1)) | J23: =G23-I23-H23 | K23: =K22+J23 | L23: =IF(21<=Inputs!B15,"Yes","")
A24: 22 | B24: =IF(22<=Inputs!B15,1,0)*MAX(0,Inputs!B13-Inputs!B14*22) | C24: =IF(22<=Inputs!B15,1,0)*Inputs!B6*MAX(0,Inputs!B13-Inputs!B14*22)/1000 | D24: =IF(22<=Inputs!B15,1,0)*Inputs!B6*MAX(0,Inputs!B13-Inputs!B14*22)/((1+Inputs!B18/100)^22) | E24: =IF(22<=Inputs!B15,1,0)*Inputs!B19*Inputs!B4/((1+Inputs!B18/100)^22) | F24: =IF(22<=Inputs!B15,1,0)*Inputs!B6*MAX(0,Inputs!B13-Inputs!B14*22)*Inputs!B20 | G24: =IF(22<=Inputs!B15,1,0)*Inputs!B6*MAX(0,Inputs!B13-Inputs!B14*22)*Inputs!B20/((1+Inputs!B18/100)^(22-1)) | H24: 0 | I24: =IF(22<=Inputs!B15,1,0)*Inputs!B19*Inputs!B4/((1+Inputs!B18/100)^(22-1)) | J24: =G24-I24-H24 | K24: =K23+J24 | L24: =IF(22<=Inputs!B15,"Yes","")
A25: 23 | B25: =IF(23<=Inputs!B15,1,0)*MAX(0,Inputs!B13-Inputs!B14*23) | C25: =IF(23<=Inputs!B15,1,0)*Inputs!B6*MAX(0,Inputs!B13-Inputs!B14*23)/1000 | D25: =IF(23<=Inputs!B15,1,0)*Inputs!B6*MAX(0,Inputs!B13-Inputs!B14*23)/((1+Inputs!B18/100)^23) | E25: =IF(23<=Inputs!B15,1,0)*Inputs!B19*Inputs!B4/((1+Inputs!B18/100)^23) | F25: =IF(23<=Inputs!B15,1,0)*Inputs!B6*MAX(0,Inputs!B13-Inputs!B14*23)*Inputs!B20 | G25: =IF(23<=Inputs!B15,1,0)*Inputs!B6*MAX(0,Inputs!B13-Inputs!B14*23)*Inputs!B20/((1+Inputs!B18/100)^(23-1)) | H25: 0 | I25: =IF(23<=Inputs!B15,1,0)*Inputs!B19*Inputs!B4/((1+Inputs!B18/100)^(23-1)) | J25: =G25-I25-H25 | K25: =K24+J25 | L25: =IF(23<=Inputs!B15,"Yes","")
A26: 24 | B26: =IF(24<=Inputs!B15,1,0)*MAX(0,Inputs!B13-Inputs!B14*24) | C26: =IF(24<=Inputs!B15,1,0)*Inputs!B6*MAX(0,Inputs!B13-Inputs!B14*24)/1000 | D26: =IF(24<=Inputs!B15,1,0)*Inputs!B6*MAX(0,Inputs!B13-Inputs!B14*24)/((1+Inputs!B18/100)^24) | E26: =IF(24<=Inputs!B15,1,0)*Inputs!B19*Inputs!B4/((1+Inputs!B18/100)^24) | F26: =IF(24<=Inputs!B15,1,0)*Inputs!B6*MAX(0,Inputs!B13-Inputs!B14*24)*Inputs!B20 | G26: =IF(24<=Inputs!B15,1,0)*Inputs!B6*MAX(0,Inputs!B13-Inputs!B14*24)*Inputs!B20/((1+Inputs!B18/100)^(24-1)) | H26: 0 | I26: =IF(24<=Inputs!B15,1,0)*Inputs!B19*Inputs!B4/((1+Inputs!B18/100)^(24-1)) | J26: =G26-I26-H26 | K26: =K25+J26 | L26: =IF(24<=Inputs!B15,"Yes","")
A27: 25 | B27: =IF(25<=Inputs!B15,1,0)*MAX(0,Inputs!B13-Inputs!B14*25) | C27: =IF(25<=Inputs!B15,1,0)*Inputs!B6*MAX(0,Inputs!B13-Inputs!B14*25)/1000 | D27: =IF(25<=Inputs!B15,1,0)*Inputs!B6*MAX(0,Inputs!B13-Inputs!B14*25)/((1+Inputs!B18/100)^25) | E27: =IF(25<=Inputs!B15,1,0)*Inputs!B19*Inputs!B4/((1+Inputs!B18/100)^25) | F27: =IF(25<=Inputs!B15,1,0)*Inputs!B6*MAX(0,Inputs!B13-Inputs!B14*25)*Inputs!B20 | G27: =IF(25<=Inputs!B15,1,0)*Inputs!B6*MAX(0,Inputs!B13-Inputs!B14*25)*Inputs!B20/((1+Inputs!B18/100)^(25-1)) | H27: 0 | I27: =IF(25<=Inputs!B15,1,0)*Inputs!B19*Inputs!B4/((1+Inputs!B18/100)^(25-1)) | J27: =G27-I27-H27 | K27: =K26+J27 | L27: =IF(25<=Inputs!B15,"Yes","")
A28: 26 | B28: =IF(26<=Inputs!B15,1,0)*MAX(0,Inputs!B13-Inputs!B14*26) | C28: =IF(26<=Inputs!B15,1,0)*Inputs!B6*MAX(0,Inputs!B13-Inputs!B14*26)/1000 | D28: =IF(26<=Inputs!B15,1,0)*Inputs!B6*MAX(0,Inputs!B13-Inputs!B14*26)/((1+Inputs!B18/100)^26) | E28: =IF(26<=Inputs!B15,1,0)*Inputs!B19*Inputs!B4/((1+Inputs!B18/100)^26) | F28: =IF(26<=Inputs!B15,1,0)*Inputs!B6*MAX(0,Inputs!B13-Inputs!B14*26)*Inputs!B20 | G28: =IF(26<=Inputs!B15,1,0)*Inputs!B6*MAX(0,Inputs!B13-Inputs!B14*26)*Inputs!B20/((1+Inputs!B18/100)^(26-1)) | H28: 0 | I28: =IF(26<=Inputs!B15,1,0)*Inputs!B19*Inputs!B4/((1+Inputs!B18/100)^(26-1)) | J28: =G28-I28-H28 | K28: =K27+J28 | L28: =IF(26<=Inputs!B15,"Yes","")
A29: 27 | B29: =IF(27<=Inputs!B15,1,0)*MAX(0,Inputs!B13-Inputs!B14*27) | C29: =IF(27<=Inputs!B15,1,0)*Inputs!B6*MAX(0,Inputs!B13-Inputs!B14*27)/1000 | D29: =IF(27<=Inputs!B15,1,0)*Inputs!B6*MAX(0,Inputs!B13-Inputs!B14*27)/((1+Inputs!B18/100)^27) | E29: =IF(27<=Inputs!B15,1,0)*Inputs!B19*Inputs!B4/((1+Inputs!B18/100)^27) | F29: =IF(27<=Inputs!B15,1,0)*Inputs!B6*MAX(0,Inputs!B13-Inputs!B14*27)*Inputs!B20 | G29: =IF(27<=Inputs!B15,1,0)*Inputs!B6*MAX(0,Inputs!B13-Inputs!B14*27)*Inputs!B20/((1+Inputs!B18/100)^(27-1)) | H29: 0 | I29: =IF(27<=Inputs!B15,1,0)*Inputs!B19*Inputs!B4/((1+Inputs!B18/100)^(27-1)) | J29: =G29-I29-H29 | K29: =K28+J29 | L29: =IF(27<=Inputs!B15,"Yes","")
A30: 28 | B30: =IF(28<=Inputs!B15,1,0)*MAX(0,Inputs!B13-Inputs!B14*28) | C30: =IF(28<=Inputs!B15,1,0)*Inputs!B6*MAX(0,Inputs!B13-Inputs!B14*28)/1000 | D30: =IF(28<=Inputs!B15,1,0)*Inputs!B6*MAX(0,Inputs!B13-Inputs!B14*28)/((1+Inputs!B18/100)^28) | E30: =IF(28<=Inputs!B15,1,0)*Inputs!B19*Inputs!B4/((1+Inputs!B18/100)^28) | F30: =IF(28<=Inputs!B15,1,0)*Inputs!B6*MAX(0,Inputs!B13-Inputs!B14*28)*Inputs!B20 | G30: =IF(28<=Inputs!B15,1,0)*Inputs!B6*MAX(0,Inputs!B13-Inputs!B14*28)*Inputs!B20/((1+Inputs!B18/100)^(28-1)) | H30: 0 | I30: =IF(28<=Inputs!B15,1,0)*Inputs!B19*Inputs!B4/((1+Inputs!B18/100)^(28-1)) | J30: =G30-I30-H30 | K30: =K29+J30 | L30: =IF(28<=Inputs!B15,"Yes","")
A31: 29 | B31: =IF(29<=Inputs!B15,1,0)*MAX(0,Inputs!B13-Inputs!B14*29) | C31: =IF(29<=Inputs!B15,1,0)*Inputs!B6*MAX(0,Inputs!B13-Inputs!B14*29)/1000 | D31: =IF(29<=Inputs!B15,1,0)*Inputs!B6*MAX(0,Inputs!B13-Inputs!B14*29)/((1+Inputs!B18/100)^29) | E31: =IF(29<=Inputs!B15,1,0)*Inputs!B19*Inputs!B4/((1+Inputs!B18/100)^29) | F31: =IF(29<=Inputs!B15,1,0)*Inputs!B6*MAX(0,Inputs!B13-Inputs!B14*29)*Inputs!B20 | G31: =IF(29<=Inputs!B15,1,0)*Inputs!B6*MAX(0,Inputs!B13-Inputs!B14*29)*Inputs!B20/((1+Inputs!B18/100)^(29-1)) | H31: 0 | I31: =IF(29<=Inputs!B15,1,0)*Inputs!B19*Inputs!B4/((1+Inputs!B18/100)^(29-1)) | J31: =G31-I31-H31 | K31: =K30+J31 | L31: =IF(29<=Inputs!B15,"Yes","")
A32: 30 | B32: =IF(30<=Inputs!B15,1,0)*MAX(0,Inputs!B13-Inputs!B14*30) | C32: =IF(30<=Inputs!B15,1,0)*Inputs!B6*MAX(0,Inputs!B13-Inputs!B14*30)/1000 | D32: =IF(30<=Inputs!B15,1,0)*Inputs!B6*MAX(0,Inputs!B13-Inputs!B14*30)/((1+Inputs!B18/100)^30) | E32: =IF(30<=Inputs!B15,1,0)*Inputs!B19*Inputs!B4/((1+Inputs!B18/100)^30) | F32: =IF(30<=Inputs!B15,1,0)*Inputs!B6*MAX(0,Inputs!B13-Inputs!B14*30)*Inputs!B20 | G32: =IF(30<=Inputs!B15,1,0)*Inputs!B6*MAX(0,Inputs!B13-Inputs!B14*30)*Inputs!B20/((1+Inputs!B18/100)^(30-1)) | H32: 0 | I32: =IF(30<=Inputs!B15,1,0)*Inputs!B19*Inputs!B4/((1+Inputs!B18/100)^(30-1)) | J32: =G32-I32-H32 | K32: =K31+J32 | L32: =IF(30<=Inputs!B15,"Yes","")
A33: 31 | B33: =IF(31<=Inputs!B15,1,0)*MAX(0,Inputs!B13-Inputs!B14*31) | C33: =IF(31<=Inputs!B15,1,0)*Inputs!B6*MAX(0,Inputs!B13-Inputs!B14*31)/1000 | D33: =IF(31<=Inputs!B15,1,0)*Inputs!B6*MAX(0,Inputs!B13-Inputs!B14*31)/((1+Inputs!B18/100)^31) | E33: =IF(31<=Inputs!B15,1,0)*Inputs!B19*Inputs!B4/((1+Inputs!B18/100)^31) | F33: =IF(31<=Inputs!B15,1,0)*Inputs!B6*MAX(0,Inputs!B13-Inputs!B14*31)*Inputs!B20 | G33: =IF(31<=Inputs!B15,1,0)*Inputs!B6*MAX(0,Inputs!B13-Inputs!B14*31)*Inputs!B20/((1+Inputs!B18/100)^(31-1)) | H33: 0 | I33: =IF(31<=Inputs!B15,1,0)*Inputs!B19*Inputs!B4/((1+Inputs!B18/100)^(31-1)) | J33: =G33-I33-H33 | K33: =K32+J33 | L33: =IF(31<=Inputs!B15,"Yes","")
A34: 32 | B34: =IF(32<=Inputs!B15,1,0)*MAX(0,Inputs!B13-Inputs!B14*32) | C34: =IF(32<=Inputs!B15,1,0)*Inputs!B6*MAX(0,Inputs!B13-Inputs!B14*32)/1000 | D34: =IF(32<=Inputs!B15,1,0)*Inputs!B6*MAX(0,Inputs!B13-Inputs!B14*32)/((1+Inputs!B18/100)^32) | E34: =IF(32<=Inputs!B15,1,0)*Inputs!B19*Inputs!B4/((1+Inputs!B18/100)^32) | F34: =IF(32<=Inputs!B15,1,0)*Inputs!B6*MAX(0,Inputs!B13-Inputs!B14*32)*Inputs!B20 | G34: =IF(32<=Inputs!B15,1,0)*Inputs!B6*MAX(0,Inputs!B13-Inputs!B14*32)*Inputs!B20/((1+Inputs!B18/100)^(32-1)) | H34: 0 | I34: =IF(32<=Inputs!B15,1,0)*Inputs!B19*Inputs!B4/((1+Inputs!B18/100)^(32-1)) | J34: =G34-I34-H34 | K34: =K33+J34 | L34: =IF(32<=Inputs!B15,"Yes","")
A35: 33 | B35: =IF(33<=Inputs!B15,1,0)*MAX(0,Inputs!B13-Inputs!B14*33) | C35: =IF(33<=Inputs!B15,1,0)*Inputs!B6*MAX(0,Inputs!B13-Inputs!B14*33)/1000 | D35: =IF(33<=Inputs!B15,1,0)*Inputs!B6*MAX(0,Inputs!B13-Inputs!B14*33)/((1+Inputs!B18/100)^33) | E35: =IF(33<=Inputs!B15,1,0)*Inputs!B19*Inputs!B4/((1+Inputs!B18/100)^33) | F35: =IF(33<=Inputs!B15,1,0)*Inputs!B6*MAX(0,Inputs!B13-Inputs!B14*33)*Inputs!B20 | G35: =IF(33<=Inputs!B15,1,0)*Inputs!B6*MAX(0,Inputs!B13-Inputs!B14*33)*Inputs!B20/((1+Inputs!B18/100)^(33-1)) | H35: 0 | I35: =IF(33<=Inputs!B15,1,0)*Inputs!B19*Inputs!B4/((1+Inputs!B18/100)^(33-1)) | J35: =G35-I35-H35 | K35: =K34+J35 | L35: =IF(33<=Inputs!B15,"Yes","")
A36: 34 | B36: =IF(34<=Inputs!B15,1,0)*MAX(0,Inputs!B13-Inputs!B14*34) | C36: =IF(34<=Inputs!B15,1,0)*Inputs!B6*MAX(0,Inputs!B13-Inputs!B14*34)/1000 | D36: =IF(34<=Inputs!B15,1,0)*Inputs!B6*MAX(0,Inputs!B13-Inputs!B14*34)/((1+Inputs!B18/100)^34) | E36: =IF(34<=Inputs!B15,1,0)*Inputs!B19*Inputs!B4/((1+Inputs!B18/100)^34) | F36: =IF(34<=Inputs!B15,1,0)*Inputs!B6*MAX(0,Inputs!B13-Inputs!B14*34)*Inputs!B20 | G36: =IF(34<=Inputs!B15,1,0)*Inputs!B6*MAX(0,Inputs!B13-Inputs!B14*34)*Inputs!B20/((1+Inputs!B18/100)^(34-1)) | H36: 0 | I36: =IF(34<=Inputs!B15,1,0)*Inputs!B19*Inputs!B4/((1+Inputs!B18/100)^(34-1)) | J36: =G36-I36-H36 | K36: =K35+J36 | L36: =IF(34<=Inputs!B15,"Yes","")
A37: 35 | B37: =IF(35<=Inputs!B15,1,0)*MAX(0,Inputs!B13-Inputs!B14*35) | C37: =IF(35<=Inputs!B15,1,0)*Inputs!B6*MAX(0,Inputs!B13-Inputs!B14*35)/1000 | D37: =IF(35<=Inputs!B15,1,0)*Inputs!B6*MAX(0,Inputs!B13-Inputs!B14*35)/((1+Inputs!B18/100)^35) | E37: =IF(35<=Inputs!B15,1,0)*Inputs!B19*Inputs!B4/((1+Inputs!B18/100)^35) | F37: =IF(35<=Inputs!B15,1,0)*Inputs!B6*MAX(0,Inputs!B13-Inputs!B14*35)*Inputs!B20 | G37: =IF(35<=Inputs!B15,1,0)*Inputs!B6*MAX(0,Inputs!B13-Inputs!B14*35)*Inputs!B20/((1+Inputs!B18/100)^(35-1)) | H37: 0 | I37: =IF(35<=Inputs!B15,1,0)*Inputs!B19*Inputs!B4/((1+Inputs!B18/100)^(35-1)) | J37: =G37-I37-H37 | K37: =K36+J37 | L37: =IF(35<=Inputs!B15,"Yes","")
A38: 36 | B38: =IF(36<=Inputs!B15,1,0)*MAX(0,Inputs!B13-Inputs!B14*36) | C38: =IF(36<=Inputs!B15,1,0)*Inputs!B6*MAX(0,Inputs!B13-Inputs!B14*36)/1000 | D38: =IF(36<=Inputs!B15,1,0)*Inputs!B6*MAX(0,Inputs!B13-Inputs!B14*36)/((1+Inputs!B18/100)^36) | E38: =IF(36<=Inputs!B15,1,0)*Inputs!B19*Inputs!B4/((1+Inputs!B18/100)^36) | F38: =IF(36<=Inputs!B15,1,0)*Inputs!B6*MAX(0,Inputs!B13-Inputs!B14*36)*Inputs!B20 | G38: =IF(36<=Inputs!B15,1,0)*Inputs!B6*MAX(0,Inputs!B13-Inputs!B14*36)*Inputs!B20/((1+Inputs!B18/100)^(36-1)) | H38: 0 | I38: =IF(36<=Inputs!B15,1,0)*Inputs!B19*Inputs!B4/((1+Inputs!B18/100)^(36-1)) | J38: =G38-I38-H38 | K38: =K37+J38 | L38: =IF(36<=Inputs!B15,"Yes","")
A39: 37 | B39: =IF(37<=Inputs!B15,1,0)*MAX(0,Inputs!B13-Inputs!B14*37) | C39: =IF(37<=Inputs!B15,1,0)*Inputs!B6*MAX(0,Inputs!B13-Inputs!B14*37)/1000 | D39: =IF(37<=Inputs!B15,1,0)*Inputs!B6*MAX(0,Inputs!B13-Inputs!B14*37)/((1+Inputs!B18/100)^37) | E39: =IF(37<=Inputs!B15,1,0)*Inputs!B19*Inputs!B4/((1+Inputs!B18/100)^37) | F39: =IF(37<=Inputs!B15,1,0)*Inputs!B6*MAX(0,Inputs!B13-Inputs!B14*37)*Inputs!B20 | G39: =IF(37<=Inputs!B15,1,0)*Inputs!B6*MAX(0,Inputs!B13-Inputs!B14*37)*Inputs!B20/((1+Inputs!B18/100)^(37-1)) | H39: 0 | I39: =IF(37<=Inputs!B15,1,0)*Inputs!B19*Inputs!B4/((1+Inputs!B18/100)^(37-1)) | J39: =G39-I39-H39 | K39: =K38+J39 | L39: =IF(37<=Inputs!B15,"Yes","")
A40: 38 | B40: =IF(38<=Inputs!B15,1,0)*MAX(0,Inputs!B13-Inputs!B14*38) | C40: =IF(38<=Inputs!B15,1,0)*Inputs!B6*MAX(0,Inputs!B13-Inputs!B14*38)/1000 | D40: =IF(38<=Inputs!B15,1,0)*Inputs!B6*MAX(0,Inputs!B13-Inputs!B14*38)/((1+Inputs!B18/100)^38) | E40: =IF(38<=Inputs!B15,1,0)*Inputs!B19*Inputs!B4/((1+Inputs!B18/100)^38) | F40: =IF(38<=Inputs!B15,1,0)*Inputs!B6*MAX(0,Inputs!B13-Inputs!B14*38)*Inputs!B20 | G40: =IF(38<=Inputs!B15,1,0)*Inputs!B6*MAX(0,Inputs!B13-Inputs!B14*38)*Inputs!B20/((1+Inputs!B18/100)^(38-1)) | H40: 0 | I40: =IF(38<=Inputs!B15,1,0)*Inputs!B19*Inputs!B4/((1+Inputs!B18/100)^(38-1)) | J40: =G40-I40-H40 | K40: =K39+J40 | L40: =IF(38<=Inputs!B15,"Yes","")
...

Sheet Results
A1: LCOE RESULTS — KEY PERFORMANCE INDICATORS
A2: Metric | B2: Value | C2: Unit | D2: Description
A3: PRIMARY OUTPUT — LEVELIZED COST OF ENERGY (LCOE)
A4: LCOE | B4: =(CAPEX!D31+SUM(Schedule!E3:E42))/(Inputs!B6+SUM(Schedule!D3:D42)) | C4: $/kWh | D4: Discounted lifetime cost divided by discounted lifetime energy
A5: LCOE ($/MWh) | B5: =B4*1000 | C5: $/MWh | D5: LCOE × 1 000
A6: LCOE Rating | B6: =IF(B4<Inputs!B23,"✓ Excellent",IF(B4<=Inputs!B24,"~ Acceptable","✗ Low")) | C6: — | D6: Excellent < 0.034 $/kWh | Acceptable ≤ 0.045 | Low > 0.045
A8: CAPITAL EXPENDITURE
A9: Total CAPEX ($) | B9: =CAPEX!D31 | C9: $ | D9: Upfront capital expenditure
A10: CAPEX per kWp ($/kWp) | B10: =CAPEX!C31 | C10: $/kWp | D10: Specific capital cost
A12: ENERGY PRODUCTION
A13: Capacity Factor (%) | B13: =Inputs!B6/(Inputs!B4*8760)*100 | C13: % | D13: Annual energy / (Capacity × 8 760 h)
A14: Lifetime Energy Production | B14: =Inputs!B6/1000+SUM(Schedule!C3:C42) | C14: MWh | D14: Total energy over project lifetime (incl. degradation)
A15: O&M NPV (Σ Discounted O&M) | B15: =SUM(Schedule!E3:E42) | C15: $ | D15: Net present value of all annual O&M costs
A17: FINANCIAL INDICATORS
A18: Year-1 Revenue ($) | B18: =Inputs!B6*Inputs!B13*Inputs!B20 | C18: $ | D18: E₀ × f₁ × tariff (first year, undiscounted)
A19: Annual O&M Cost ($/yr) | B19: =Inputs!B19*Inputs!B4 | C19: $/yr | D19: O&M ($/kWp/yr) × system capacity
A20: Simple Payback Period | B20: =IF(Inputs!B6*Inputs!B13*Inputs!B20>Inputs!B19*Inputs!B4,CAPEX!D31/(Inputs!B6*Inputs!B13*Inputs!B20-Inputs!B19*Inputs!B4),"N/A") | C20: years | D20: CAPEX / (Year-1 Revenue − O&M) — undiscounted
A21: Discounted Payback (TRI) | B21: =IFERROR( (MATCH(TRUE,Schedule!K3:K42>=0,0)-1) + ABS(INDEX(Schedule!K3:K42,MATCH(TRUE,Schedule!K3:K42>=0,0)-1)) / INDEX(Schedule!J3:J42,MATCH(TRUE,Schedule!K3:K42>=0,0)),"N/A") | C21: years | D21: Year when cumulative discounted cash flow crosses zero
A22: Project NPV (at WACC) | B22: =INDEX(Schedule!K3:K42,MIN(Inputs!B15,40)) | C22: $ | D22: Cumulative discounted CF at end of project lifetime
A23: Project IRR | B23: =IFERROR(IRR(F81:F121,0.05)*100,"N/A") | C23: % | D23: Internal rate of return on undiscounted net cash flows
A25: CAPEX BREAKDOWN BY CATEGORY
A26: Category | B26: $/kWp | C26: Total ($) | D26: % of CAPEX
A27: Module & Inverter Hardware | B27: =CAPEX!C6 | C27: =CAPEX!D6 | D27: =IF(CAPEX!C31=0,0,CAPEX!C6/CAPEX!C31)
A28: Balance of System (BOS) | B28: =CAPEX!C14 | C28: =CAPEX!D14 | D28: =IF(CAPEX!C31=0,0,CAPEX!C14/CAPEX!C31)
A29: Installation | B29: =CAPEX!C20 | C29: =CAPEX!D20 | D29: =IF(CAPEX!C31=0,0,CAPEX!C20/CAPEX!C31)
A30: Soft Costs | B30: =CAPEX!C29 | C30: =CAPEX!D29 | D30: =IF(CAPEX!C31=0,0,CAPEX!C29/CAPEX!C31)
F80: IRR helper — do not edit
F81: =-CAPEX!D31
F82: =IF(1<=Inputs!B15,Schedule!F3-Inputs!B19*Inputs!B4,0)
F83: =IF(2<=Inputs!B15,Schedule!F4-Inputs!B19*Inputs!B4,0)
F84: =IF(3<=Inputs!B15,Schedule!F5-Inputs!B19*Inputs!B4,0)
F85: =IF(4<=Inputs!B15,Schedule!F6-Inputs!B19*Inputs!B4,0)
F86: =IF(5<=Inputs!B15,Schedule!F7-Inputs!B19*Inputs!B4,0)
F87: =IF(6<=Inputs!B15,Schedule!F8-Inputs!B19*Inputs!B4,0)
F88: =IF(7<=Inputs!B15,Schedule!F9-Inputs!B19*Inputs!B4,0)
F89: =IF(8<=Inputs!B15,Schedule!F10-Inputs!B19*Inputs!B4,0)
F90: =IF(9<=Inputs!B15,Schedule!F11-Inputs!B19*Inputs!B4,0)
F91: =IF(10<=Inputs!B15,Schedule!F12-Inputs!B19*Inputs!B4,0)
F92: =IF(11<=Inputs!B15,Schedule!F13-Inputs!B19*Inputs!B4,0)
F93: =IF(12<=Inputs!B15,Schedule!F14-Inputs!B19*Inputs!B4,0)
...

Sheet Sensitivity
A1: SENSITIVITY ANALYSIS — TORNADO (±20 % parameter variation)
A2: Parameter | B2: Base LCOE ($/kWh) | C2: LCOE at −20% ($/kWh) | D2: LCOE at +20% ($/kWh) | E2: Low Impact ($/kWh) | F2: High Impact ($/kWh) | G2: Swing ($/kWh)
A3: CAPEX Components | B3: =Results!B4 | C3: =IF(((Inputs!B6*1)+SUMPRODUCT(IF(ROW(INDIRECT("1:40"))<=Inputs!B15,(Inputs!B6*1)*MAX(0,Inputs!B13-(Inputs!B14*1)*ROW(INDIRECT("1:40")))/(1+(Inputs!B18/100))^ROW(INDIRECT("1:40")),0)))=0,0,((CAPEX!D31*0.8)+SUMPRODUCT(IF(ROW(INDIRECT("1:40"))<=Inputs!B15,(Inputs!B19*Inputs!B4*1)/(1+(Inputs!B18/100))^ROW(INDIRECT("1:40")),0)))/((Inputs!B6*1)+SUMPRODUCT(IF(ROW(INDIRECT("1:40"))<=Inputs!B15,(Inputs!B6*1)*MAX(0,Inputs!B13-(Inputs!B14*1)*ROW(INDIRECT("1:40")))/(1+(Inputs!B18/100))^ROW(INDIRECT("1:40")),0)))) | D3: =IF(((Inputs!B6*1)+SUMPRODUCT(IF(ROW(INDIRECT("1:40"))<=Inputs!B15,(Inputs!B6*1)*MAX(0,Inputs!B13-(Inputs!B14*1)*ROW(INDIRECT("1:40")))/(1+(Inputs!B18/100))^ROW(INDIRECT("1:40")),0)))=0,0,((CAPEX!D31*1.2)+SUMPRODUCT(IF(ROW(INDIRECT("1:40"))<=Inputs!B15,(Inputs!B19*Inputs!B4*1)/(1+(Inputs!B18/100))^ROW(INDIRECT("1:40")),0)))/((Inputs!B6*1)+SUMPRODUCT(IF(ROW(INDIRECT("1:40"))<=Inputs!B15,(Inputs!B6*1)*MAX(0,Inputs!B13-(Inputs!B14*1)*ROW(INDIRECT("1:40")))/(1+(Inputs!B18/100))^ROW(INDIRECT("1:40")),0)))) | E3: =C3-B3 | F3: =D3-B3 | G3: =ABS(D3-C3)
A4: Discount Rate (WACC) | B4: =Results!B4 | C4: =IF(((Inputs!B6*1)+SUMPRODUCT(IF(ROW(INDIRECT("1:40"))<=Inputs!B15,(Inputs!B6*1)*MAX(0,Inputs!B13-(Inputs!B14*1)*ROW(INDIRECT("1:40")))/(1+(Inputs!B18*0.8/100))^ROW(INDIRECT("1:40")),0)))=0,0,((CAPEX!D31*1)+SUMPRODUCT(IF(ROW(INDIRECT("1:40"))<=Inputs!B15,(Inputs!B19*Inputs!B4*1)/(1+(Inputs!B18*0.8/100))^ROW(INDIRECT("1:40")),0)))/((Inputs!B6*1)+SUMPRODUCT(IF(ROW(INDIRECT("1:40"))<=Inputs!B15,(Inputs!B6*1)*MAX(0,Inputs!B13-(Inputs!B14*1)*ROW(INDIRECT("1:40")))/(1+(Inputs!B18*0.8/100))^ROW(INDIRECT("1:40")),0)))) | D4: =IF(((Inputs!B6*1)+SUMPRODUCT(IF(ROW(INDIRECT("1:40"))<=Inputs!B15,(Inputs!B6*1)*MAX(0,Inputs!B13-(Inputs!B14*1)*ROW(INDIRECT("1:40")))/(1+(Inputs!B18*1.2/100))^ROW(INDIRECT("1:40")),0)))=0,0,((CAPEX!D31*1)+SUMPRODUCT(IF(ROW(INDIRECT("1:40"))<=Inputs!B15,(Inputs!B19*Inputs!B4*1)/(1+(Inputs!B18*1.2/100))^ROW(INDIRECT("1:40")),0)))/((Inputs!B6*1)+SUMPRODUCT(IF(ROW(INDIRECT("1:40"))<=Inputs!B15,(Inputs!B6*1)*MAX(0,Inputs!B13-(Inputs!B14*1)*ROW(INDIRECT("1:40")))/(1+(Inputs!B18*1.2/100))^ROW(INDIRECT("1:40")),0)))) | E4: =C4-B4 | F4: =D4-B4 | G4: =ABS(D4-C4)
A5: Annual Energy | B5: =Results!B4 | C5: =IF(((Inputs!B6*0.8)+SUMPRODUCT(IF(ROW(INDIRECT("1:40"))<=Inputs!B15,(Inputs!B6*0.8)*MAX(0,Inputs!B13-(Inputs!B14*1)*ROW(INDIRECT("1:40")))/(1+(Inputs!B18/100))^ROW(INDIRECT("1:40")),0)))=0,0,((CAPEX!D31*1)+SUMPRODUCT(IF(ROW(INDIRECT("1:40"))<=Inputs!B15,(Inputs!B19*Inputs!B4*1)/(1+(Inputs!B18/100))^ROW(INDIRECT("1:40")),0)))/((Inputs!B6*0.8)+SUMPRODUCT(IF(ROW(INDIRECT("1:40"))<=Inputs!B15,(Inputs!B6*0.8)*MAX(0,Inputs!B13-(Inputs!B14*1)*ROW(INDIRECT("1:40")))/(1+(Inputs!B18/100))^ROW(INDIRECT("1:40")),0)))) | D5: =IF(((Inputs!B6*1.2)+SUMPRODUCT(IF(ROW(INDIRECT("1:40"))<=Inputs!B15,(Inputs!B6*1.2)*MAX(0,Inputs!B13-(Inputs!B14*1)*ROW(INDIRECT("1:40")))/(1+(Inputs!B18/100))^ROW(INDIRECT("1:40")),0)))=0,0,((CAPEX!D31*1)+SUMPRODUCT(IF(ROW(INDIRECT("1:40"))<=Inputs!B15,(Inputs!B19*Inputs!B4*1)/(1+(Inputs!B18/100))^ROW(INDIRECT("1:40")),0)))/((Inputs!B6*1.2)+SUMPRODUCT(IF(ROW(INDIRECT("1:40"))<=Inputs!B15,(Inputs!B6*1.2)*MAX(0,Inputs!B13-(Inputs!B14*1)*ROW(INDIRECT("1:40")))/(1+(Inputs!B18/100))^ROW(INDIRECT("1:40")),0)))) | E5: =C5-B5 | F5: =D5-B5 | G5: =ABS(D5-C5)
A6: O&M Cost | B6: =Results!B4 | C6: =IF(((Inputs!B6*1)+SUMPRODUCT(IF(ROW(INDIRECT("1:40"))<=Inputs!B15,(Inputs!B6*1)*MAX(0,Inputs!B13-(Inputs!B14*1)*ROW(INDIRECT("1:40")))/(1+(Inputs!B18/100))^ROW(INDIRECT("1:40")),0)))=0,0,((CAPEX!D31*1)+SUMPRODUCT(IF(ROW(INDIRECT("1:40"))<=Inputs!B15,(Inputs!B19*Inputs!B4*0.8)/(1+(Inputs!B18/100))^ROW(INDIRECT("1:40")),0)))/((Inputs!B6*1)+SUMPRODUCT(IF(ROW(INDIRECT("1:40"))<=Inputs!B15,(Inputs!B6*1)*MAX(0,Inputs!B13-(Inputs!B14*1)*ROW(INDIRECT("1:40")))/(1+(Inputs!B18/100))^ROW(INDIRECT("1:40")),0)))) | D6: =IF(((Inputs!B6*1)+SUMPRODUCT(IF(ROW(INDIRECT("1:40"))<=Inputs!B15,(Inputs!B6*1)*MAX(0,Inputs!B13-(Inputs!B14*1)*ROW(INDIRECT("1:40")))/(1+(Inputs!B18/100))^ROW(INDIRECT("1:40")),0)))=0,0,((CAPEX!D31*1)+SUMPRODUCT(IF(ROW(INDIRECT("1:40"))<=Inputs!B15,(Inputs!B19*Inputs!B4*1.2)/(1+(Inputs!B18/100))^ROW(INDIRECT("1:40")),0)))/((Inputs!B6*1)+SUMPRODUCT(IF(ROW(INDIRECT("1:40"))<=Inputs!B15,(Inputs!B6*1)*MAX(0,Inputs!B13-(Inputs!B14*1)*ROW(INDIRECT("1:40")))/(1+(Inputs!B18/100))^ROW(INDIRECT("1:40")),0)))) | E6: =C6-B6 | F6: =D6-B6 | G6: =ABS(D6-C6)
A7: Project Lifetime | B7: =Results!B4 | C7: =IF(((Inputs!B6*1)+SUMPRODUCT(IF(ROW(INDIRECT("1:40"))<=ROUND(Inputs!B15*0.8,0),(Inputs!B6*1)*MAX(0,Inputs!B13-(Inputs!B14*1)*ROW(INDIRECT("1:40")))/(1+(Inputs!B18/100))^ROW(INDIRECT("1:40")),0)))=0,0,((CAPEX!D31*1)+SUMPRODUCT(IF(ROW(INDIRECT("1:40"))<=ROUND(Inputs!B15*0.8,0),(Inputs!B19*Inputs!B4*1)/(1+(Inputs!B18/100))^ROW(INDIRECT("1:40")),0)))/((Inputs!B6*1)+SUMPRODUCT(IF(ROW(INDIRECT("1:40"))<=ROUND(Inputs!B15*0.8,0),(Inputs!B6*1)*MAX(0,Inputs!B13-(Inputs!B14*1)*ROW(INDIRECT("1:40")))/(1+(Inputs!B18/100))^ROW(INDIRECT("1:40")),0)))) | D7: =IF(((Inputs!B6*1)+SUMPRODUCT(IF(ROW(INDIRECT("1:40"))<=ROUND(Inputs!B15*1.2,0),(Inputs!B6*1)*MAX(0,Inputs!B13-(Inputs!B14*1)*ROW(INDIRECT("1:40")))/(1+(Inputs!B18/100))^ROW(INDIRECT("1:40")),0)))=0,0,((CAPEX!D31*1)+SUMPRODUCT(IF(ROW(INDIRECT("1:40"))<=ROUND(Inputs!B15*1.2,0),(Inputs!B19*Inputs!B4*1)/(1+(Inputs!B18/100))^ROW(INDIRECT("1:40")),0)))/((Inputs!B6*1)+SUMPRODUCT(IF(ROW(INDIRECT("1:40"))<=ROUND(Inputs!B15*1.2,0),(Inputs!B6*1)*MAX(0,Inputs!B13-(Inputs!B14*1)*ROW(INDIRECT("1:40")))/(1+(Inputs!B18/100))^ROW(INDIRECT("1:40")),0)))) | E7: =C7-B7 | F7: =D7-B7 | G7: =ABS(D7-C7)
A8: Degradation Rate | B8: =Results!B4 | C8: =IF(((Inputs!B6*1)+SUMPRODUCT(IF(ROW(INDIRECT("1:40"))<=Inputs!B15,(Inputs!B6*1)*MAX(0,Inputs!B13-(Inputs!B14*0.8)*ROW(INDIRECT("1:40")))/(1+(Inputs!B18/100))^ROW(INDIRECT("1:40")),0)))=0,0,((CAPEX!D31*1)+SUMPRODUCT(IF(ROW(INDIRECT("1:40"))<=Inputs!B15,(Inputs!B19*Inputs!B4*1)/(1+(Inputs!B18/100))^ROW(INDIRECT("1:40")),0)))/((Inputs!B6*1)+SUMPRODUCT(IF(ROW(INDIRECT("1:40"))<=Inputs!B15,(Inputs!B6*1)*MAX(0,Inputs!B13-(Inputs!B14*0.8)*ROW(INDIRECT("1:40")))/(1+(Inputs!B18/100))^ROW(INDIRECT("1:40")),0)))) | D8: =IF(((Inputs!B6*1)+SUMPRODUCT(IF(ROW(INDIRECT("1:40"))<=Inputs!B15,(Inputs!B6*1)*MAX(0,Inputs!B13-(Inputs!B14*1.2)*ROW(INDIRECT("1:40")))/(1+(Inputs!B18/100))^ROW(INDIRECT("1:40")),0)))=0,0,((CAPEX!D31*1)+SUMPRODUCT(IF(ROW(INDIRECT("1:40"))<=Inputs!B15,(Inputs!B19*Inputs!B4*1)/(1+(Inputs!B18/100))^ROW(INDIRECT("1:40")),0)))/((Inputs!B6*1)+SUMPRODUCT(IF(ROW(INDIRECT("1:40"))<=Inputs!B15,(Inputs!B6*1)*MAX(0,Inputs!B13-(Inputs!B14*1.2)*ROW(INDIRECT("1:40")))/(1+(Inputs!B18/100))^ROW(INDIRECT("1:40")),0)))) | E8: =C8-B8 | F8: =D8-B8 | G8: =ABS(D8-C8)
A9: Tariff / PPA ← does not affect LCOE | B9: =Results!B4 | C9: =Results!B4 | D9: =Results!B4 | E9: 0 | F9: 0 | G9: 0
A11: Each row varies ONE parameter by ±20 % while holding all others at base values. Swing = |LCOE(+20%) − LCOE(−20%)|. Tariff/PPA does not enter the LCOE formula (only IRR & NPV are tariff-sensitive).
